<!--Generated from parameters file
D:/Andres/Code/Data/Glove/Bart_Wave_Andres_Right_Arm.mat 26-Apr-2018 09:34:36
-->
<mujoco>
    <option apirate="50" gravity="0 0 0">
        <flag clampctrl="disable" contact="enable" gravity="disable"/>
    </option>
    <default>
        <default class="arm">
            <geom rgba="0.7 0.49 0.343 0.2401" contype="0" conaffinity="0" group="1"/>
            <!--joint damping="0.2" armature="0.01" range="-3.14 3.14"/-->
            <joint damping="0.9" armature="0.01" range="-3.14 3.14"/>
            <position ctrllimited="true" kp="20" ctrlrange="-3.14 3.14"/>
            <!--velocity ctrllimited="true" kv="1" ctrlrange="-3.14 3.14"/-->
        </default>
        <default class="ho">
            <geom type="sphere" size="2e-3" rgba="0.5 0.0 0.5 1.0" group="3" contype="0" conaffinity="0"/>
        </default>
        <default class="to">
            <geom type="sphere" size="2e-3" rgba="1.0 1.0 0.0 1.0" group="3" contype="0" conaffinity="0"/>
        </default>
    </default>
    
    <worldbody>
        <!--
        All rotation and main reference axis preserve the muscoloskeletal model order.
        However, the model is rotated to around X to preserve gravity direction
        in MUJuCo (towards -Z)
        -->
        <body childclass="ho" name="ho1" mocap="true"><geom rgba="0.5 0.0 0.5 1.0"/></body>
        <body childclass="ho" name="ho2" mocap="true"><geom rgba="0.5 0.0 0.5 1.0"/></body>
        <body childclass="ho" name="ho3" mocap="true"><geom rgba="0.5 0.0 0.5 1.0"/></body>
        <body childclass="ho" name="ho4" mocap="true"><geom rgba="0.5 0.0 0.5 1.0"/></body>
        <body childclass="ho" name="ho5" mocap="true"><geom rgba="0.5 0.0 0.5 1.0"/></body>
        <body childclass="ho" name="ho6" mocap="true"><geom rgba="0.5 0.0 0.5 1.0"/></body>
        <body childclass="ho" name="ho7" mocap="true"><geom rgba="0.5 0.0 0.5 1.0"/></body>
        <body childclass="ho" name="ho8" mocap="true"><geom rgba="0.5 0.0 0.5 1.0"/></body>
        <body childclass="ho" name="ho9" mocap="true"><geom rgba="0.5 0.0 0.5 1.0"/></body>
        <body childclass="ho" name="ho10" mocap="true"><geom rgba="0.5 0.0 0.5 1.0"/></body>
        <body childclass="ho" name="ho11" mocap="true"><geom rgba="0.5 0.0 0.5 1.0"/></body>
        <body childclass="ho" name="ho12" mocap="true"><geom rgba="0.5 0.0 0.5 1.0"/></body>
        <body childclass="ho" name="ho13" mocap="true"><geom rgba="0.5 0.0 0.5 1.0"/></body>
        <body childclass="ho" name="ho14" mocap="true"><geom rgba="0.5 0.0 0.5 1.0"/></body>
        <body childclass="ho" name="ho15" mocap="true"><geom rgba="0.5 0.0 0.5 1.0"/></body>
        <body childclass="ho" name="ho16" mocap="true"><geom rgba="0.5 0.0 0.5 1.0"/></body>
        <body childclass="ho" name="ho17" mocap="true"><geom rgba="0.5 0.0 0.5 1.0"/></body>
        <body childclass="ho" name="ho18" mocap="true"><geom rgba="0.5 0.0 0.5 1.0"/></body>
        <body childclass="ho" name="ho19" mocap="true"><geom rgba="0.5 0.0 0.5 1.0"/></body>
        <body childclass="ho" name="ho20" mocap="true"><geom rgba="0.5 0.0 0.5 1.0"/></body>
        <body childclass="ho" name="ho21" mocap="true"><geom rgba="0.0 1.0 1.0 1.0"/></body>
        <body childclass="ho" name="ho22" mocap="true"><geom rgba="0.5 0.0 0.5 1.0"/></body>
        <body childclass="ho" name="ho23" mocap="true"><geom rgba="0.5 0.0 0.5 1.0"/></body>
        <body childclass="ho" name="ho24" mocap="true"><geom rgba="0.0 1.0 1.0 1.0"/></body>
        <body childclass="ho" name="ho25" mocap="true"><geom rgba="0.0 1.0 1.0 1.0"/></body>
        <body childclass="ho" name="ho26" mocap="true"><geom rgba="0.5 0.0 0.5 1.0"/></body>
        <body childclass="ho" name="ho27" mocap="true"><geom rgba="0.0 1.0 1.0 1.0"/></body>
        <body childclass="ho" name="ho28" mocap="true"><geom rgba="0.0 1.0 1.0 1.0"/></body>
        <body childclass="ho" name="ho29" mocap="true"><geom rgba="0.0 1.0 1.0 1.0"/></body>
        <body childclass="ho" name="ho30" mocap="true"><geom rgba="0.0 1.0 1.0 1.0"/></body>
        <body childclass="ho" name="ho31" mocap="true"><geom rgba="0.0 1.0 1.0 1.0"/></body>

        <body childclass="arm" pos=" -0.34 -0.06 0.25">
            <body name="upperarm" pos="0 0 0" euler="1.578 0 0">
                <geom type="box" size=" 0.0075 0.1 0.0075" pos=" 0 -0.1 0"/>
                <joint name="j30" type="hinge" axis="0 0 1"/>
                <joint name="j31" type="hinge" axis="-1 0 0"/>
                <joint name="j32" type="hinge" axis="0 -1 0"/>
                <body name="lowerarm" pos=" 0 -0.2 0">
                    <!-- an artificial rotation (euler) offset is given to the arm to prevent occlusion of the hand-->
                    <geom type="box" size=" 0.005 0.105 0.005" pos=" 0 -0.105 0" user="0.2 0 -0.2"/>
                    <joint name="j29" type="hinge" axis="0 0 1"/>
                    <!--Wrist is a dummy member to make use of local coordinates from tracking respect to hand center-->
                    <body name="wrist" pos=" 0 -0.21 0">
                        <joint name="j26" type="hinge" axis="0 -1 0"/>
                        <joint name="j27" type="hinge" axis="0 0 1"/>
                        <joint name="j28" type="hinge" axis="-1 0 0"/>
                        <!--Dummy object, seems to be required, also for vis.-->
                        <geom type="sphere" size="3e-3" group="3"/>
                        <body name="hand" pos=" 0.011377505 -0.03125 -0.00875">
                            <!-- this is a hand palm object which is mostly decorative-->
                            <geom type="box" size="15.5e-3 12.5e-3 2.5e-3" pos="0.008 0.01 0.003" contype="1" conaffinity="0"/>
                            
                            <!--Fingers-->
                            <body name="f1pp" pos=" -0.015 0.02 0.0168">
                                <joint name="j1" type="hinge" axis="-1 0 0"/>
                                <joint name="j2" type="hinge" axis="0 0 1"/>
                                <joint name="j3" type="hinge" axis="0 -1 0"/>
                                <geom type="capsule" euler=" 1.5707963 0 0" size=" 0.006 0.012" pos=" 0 -0.012 0" contype="1" conaffinity="0"/>
                                <body name="f1mp"pos=" 0 -0.024 0">
                                    <joint name="j4" type="hinge" axis="-1 0 0"/>
                                    <geom type="capsule" euler=" 1.5707963 0 0" size=" 0.006 0.011" pos=" 0 -0.011 0" contype="1" conaffinity="0"/>
                                    <body name="f1dp"pos=" 0 -0.022 0">
                                        <joint name="j5" type="hinge" axis="-1 0 0"/>
                                        <geom type="capsule" euler=" 1.5707963 0 0" size=" 0.006 0.0015" pos=" 0 -0.0015 0" contype="5" conaffinity="0"/>
                                        <geom name="f1t" class="to" pos=" 0 -0.009 0"/>
                                    </body>
                                </body>
                            </body>
                        
                            <body name="f2pp" pos=" -0.012 -0.022 0.008">
                                <joint name="j6" type="hinge" axis="-1 0 0"/>
                                <joint name="j7" type="hinge" axis="0 0 1"/>
                                <joint name="j8" type="hinge" axis="0 -1 0"/>
                                <geom type="capsule" euler=" 1.5707963 0 0" size=" 0.0055 0.013" pos=" 0 -0.013 0" contype="1" conaffinity="0"/>
                                <body name="f2mp"pos=" 0 -0.026 0">
                                    <joint name="j9" type="hinge" axis="-1 0 0"/>
                                    <geom type="capsule" euler=" 1.5707963 0 0" size=" 0.0055 0.0085" pos=" 0 -0.0085 0" contype="1" conaffinity="0"/>
                                    <body name="f2dp"pos=" 0 -0.017 0">
                                        <joint name="j10" type="hinge" axis="-1 0 0"/>
                                        <geom type="capsule" euler=" 1.5707963 0 0" size=" 0.0055 0.00125" pos=" 0 -0.00125 0" contype="3" conaffinity="0"/>
                                        <geom name="f2t" class="to" pos=" 0 -0.008 0"/>
                                    </body>
                                </body>
                            </body>
                        
                            <body name="f3pp" pos=" -0.0027 -0.02 0.008">
                                <joint name="j11" type="hinge" axis="-1 0 0"/>
                                <joint name="j12" type="hinge" axis="0 0 1"/>
                                <joint name="j13" type="hinge" axis="0 -1 0"/>
                                <geom type="capsule" euler=" 1.5707963 0 0" size=" 0.0055 0.016" pos=" 0 -0.016 0" contype="9" conaffinity="0"/>
                                <body name="f3mp"pos=" 0 -0.032 0">
                                    <joint name="j14" type="hinge" axis="-1 0 0"/>
                                    <geom type="capsule" euler=" 1.5707963 0 0" size=" 0.0055 0.011" pos=" 0 -0.011 0" contype="9" conaffinity="0"/>
                                    <body name="f3dp"pos=" 0 -0.022 0">
                                        <joint name="j15" type="hinge" axis="-1 0 0"/>
                                        <geom type="capsule" euler=" 1.5707963 0 0" size=" 0.0055 0.00175" pos=" 0 -0.00175 0" contype="11" conaffinity="0"/>
                                        <geom name="f3t" class="to" pos=" 0 -0.009 0"/>
                                    </body>
                                </body>
                            </body>
                        
                            <body name="f4pp" pos=" 0.0067 -0.019 0.008">
                                <joint name="j16" type="hinge" axis="-1 0 0"/>
                                <joint name="j17" type="hinge" axis="0 0 1"/>
                                <joint name="j18" type="hinge" axis="0 -1 0"/>
                                <geom type="capsule" euler=" 1.5707963 0 0" size=" 0.0055 0.015" pos=" 0 -0.015 0" contype="9" conaffinity="0"/>
                                <body name="f4mp"pos=" 0 -0.03 0">
                                    <joint name="j19" type="hinge" axis="-1 0 0"/>
                                    <geom type="capsule" euler=" 1.5707963 0 0" size=" 0.0055 0.011" pos=" 0 -0.011 0" contype="9" conaffinity="0"/>
                                    <body name="f4dp"pos=" 0 -0.022 0">
                                        <joint name="j20" type="hinge" axis="-1 0 0"/>
                                        <geom type="capsule" euler=" 1.5707963 0 0" size=" 0.0055 0.00175" pos=" 0 -0.00175 0" contype="9" conaffinity="0"/>
                                        <geom name="f4t" class="to" pos=" 0 -0.009 0"/>
                                    </body>
                                </body>
                            </body>
                        
                            <body name="f5pp" pos=" 0.016 -0.014 0.011">
                                <joint name="j21" type="hinge" axis="-1 0 0"/>
                                <joint name="j22" type="hinge" axis="0 0 1"/>
                                <joint name="j23" type="hinge" axis="0 -1 0"/>
                                <geom type="capsule" euler=" 1.5707963 0 0" size=" 0.005 0.013" pos=" 0 -0.013 0" contype="1" conaffinity="0"/>
                                <body name="f5mp"pos=" 0 -0.026 0">
                                    <joint name="j24" type="hinge" axis="-1 0 0"/>
                                    <geom type="capsule" euler=" 1.5707963 0 0" size=" 0.005 0.0085" pos=" 0 -0.0085 0" contype="1" conaffinity="0"/>
                                    <body name="f5dp"pos=" 0 -0.017 0">
                                        <joint name="j25" type="hinge" axis="-1 0 0"/>
                                        <geom type="capsule" euler=" 1.5707963 0 0" size=" 0.005 0.0015" pos=" 0 -0.0015 0" contype="1" conaffinity="0"/>
                                        <geom name="f5t" class="to" pos=" 0 -0.008 0"/>
                                    </body>
                                </body>
                            </body>
                        
                        </body>
                    </body>
                </body>
            </body>
        </body>        
    </worldbody>
    
    <actuator>
        <position name="a1" class="arm" joint="j1"/>
        <position name="a2" class="arm" joint="j2"/>
        <position name="a3" class="arm" joint="j3"/>
        <position name="a4" class="arm" joint="j4"/>
        <position name="a5" class="arm" joint="j5"/>
        <position name="a6" class="arm" joint="j6"/>
        <position name="a7" class="arm" joint="j7"/>
        <position name="a8" class="arm" joint="j8"/>
        <position name="a9" class="arm" joint="j9"/>
        <position name="a10" class="arm" joint="j10"/>
        <position name="a11" class="arm" joint="j11"/>
        <position name="a12" class="arm" joint="j12"/>
        <position name="a13" class="arm" joint="j13"/>
        <position name="a14" class="arm" joint="j14"/>
        <position name="a15" class="arm" joint="j15"/>
        <position name="a16" class="arm" joint="j16"/>
        <position name="a17" class="arm" joint="j17"/>
        <position name="a18" class="arm" joint="j18"/>
        <position name="a19" class="arm" joint="j19"/>
        <position name="a20" class="arm" joint="j20"/>
        <position name="a21" class="arm" joint="j21"/>
        <position name="a22" class="arm" joint="j22"/>
        <position name="a23" class="arm" joint="j23"/>
        <position name="a24" class="arm" joint="j24"/>
        <position name="a25" class="arm" joint="j25"/>
        <position name="a26" class="arm" joint="j26"/>
        <position name="a27" class="arm" joint="j27"/>
        <position name="a28" class="arm" joint="j28"/>
        <position name="a29" class="arm" joint="j29"/>
        <position name="a30" class="arm" joint="j30"/>
        <position name="a31" class="arm" joint="j31"/>
        <position name="a32" class="arm" joint="j32"/>

	</actuator>
    
    <sensor>
        <jointpos name="s1" joint="j1"/>
        <jointpos name="s2" joint="j2"/>
        <jointpos name="s3" joint="j3"/>
        <jointpos name="s4" joint="j4"/>
        <jointpos name="s5" joint="j5"/>
        <jointpos name="s6" joint="j6"/>
        <jointpos name="s7" joint="j7"/>
        <jointpos name="s8" joint="j8"/>
        <jointpos name="s9" joint="j9"/>
        <jointpos name="s10" joint="j10"/>
        <jointpos name="s11" joint="j11"/>
        <jointpos name="s12" joint="j12"/>
        <jointpos name="s13" joint="j13"/>
        <jointpos name="s14" joint="j14"/>
        <jointpos name="s15" joint="j15"/>
        <jointpos name="s16" joint="j16"/>
        <jointpos name="s17" joint="j17"/>
        <jointpos name="s18" joint="j18"/>
        <jointpos name="s19" joint="j19"/>
        <jointpos name="s20" joint="j20"/>
        <jointpos name="s21" joint="j21"/>
        <jointpos name="s22" joint="j22"/>
        <jointpos name="s23" joint="j23"/>
        <jointpos name="s24" joint="j24"/>
        <jointpos name="s25" joint="j25"/>
        <jointpos name="s26" joint="j26"/>
        <jointpos name="s27" joint="j27"/>
        <jointpos name="s28" joint="j28"/>
        <jointpos name="s29" joint="j29"/>
        <jointpos name="s30" joint="j30"/>
        <jointpos name="s31" joint="j31"/>
        <jointpos name="s32" joint="j32"/>
        <actuatorfrc actuator="a1"/>
        <actuatorfrc actuator="a2"/>
        <actuatorfrc actuator="a3"/>
        <actuatorfrc actuator="a4"/>
        <actuatorfrc actuator="a5"/>
        <actuatorfrc actuator="a6"/>
        <actuatorfrc actuator="a7"/>
        <actuatorfrc actuator="a8"/>
        <actuatorfrc actuator="a9"/>
        <actuatorfrc actuator="a10"/>
        <actuatorfrc actuator="a11"/>
        <actuatorfrc actuator="a12"/>
        <actuatorfrc actuator="a13"/>
        <actuatorfrc actuator="a14"/>
        <actuatorfrc actuator="a15"/>
        <actuatorfrc actuator="a16"/>
        <actuatorfrc actuator="a17"/>
        <actuatorfrc actuator="a18"/>
        <actuatorfrc actuator="a19"/>
        <actuatorfrc actuator="a20"/>
        <actuatorfrc actuator="a21"/>
        <actuatorfrc actuator="a22"/>
        <actuatorfrc actuator="a23"/>
        <actuatorfrc actuator="a24"/>
        <actuatorfrc actuator="a25"/>
        <actuatorfrc actuator="a26"/>
        <actuatorfrc actuator="a27"/>
        <actuatorfrc actuator="a28"/>
        <actuatorfrc actuator="a29"/>
        <actuatorfrc actuator="a30"/>
        <actuatorfrc actuator="a31"/>
        <actuatorfrc actuator="a32"/>
        <framepos objtype="geom" objname="f1t"/>
        <framepos objtype="geom" objname="f2t"/>
        <framepos objtype="geom" objname="f3t"/>
        <framepos objtype="geom" objname="f4t"/>
        <framepos objtype="geom" objname="f5t"/>

    </sensor>
</mujoco>